<robot
  name="Heol_humanoid">
  <link
    name="pelvis">
    <inertial>
      <origin
        xyz="0.0410669745819321 -0.0379110717402652 0.0421828125034158"
        rpy="0 0 0" />
      <mass
        value="0.0572942260553945" />
      <inertia
        ixx="3.65121025707978E-05"
        ixy="2.9900783694598E-07"
        ixz="4.85882286230636E-07"
        iyy="2.12489482613664E-05"
        iyz="-3.35587468839814E-06"
        izz="2.000430429396E-05" />
    </inertial>
    <visual>
      <origin
        xyz="0 0 0"
        rpy="0 0 0" />
      <geometry>
        <mesh
          filename="package://Heol_humanoid/meshes/pelvis.STL" />
      </geometry>
      <material
        name="">
        <color
          rgba="0.752941176470588 0.752941176470588 0.752941176470588 1" />
      </material>
    </visual>
    <collision>
      <origin
        xyz="0 0 0"
        rpy="0 0 0" />
      <geometry>
        <mesh
          filename="package://Heol_humanoid/meshes/pelvis.STL" />
      </geometry>
    </collision>
  </link>
  <link
    name="l_hip">
    <inertial>
      <origin
        xyz="-0.0270835640140282 0.0231158477663268 0.0237291455019634"
        rpy="0 0 0" />
      <mass
        value="0.0238887563110607" />
      <inertia
        ixx="5.49518226158328E-06"
        ixy="6.82907038074934E-07"
        ixz="-1.00493628454709E-06"
        iyy="4.44318183140713E-06"
        iyz="-4.31099554695611E-07"
        izz="6.27728430763791E-06" />
    </inertial>
    <visual>
      <origin
        xyz="0 0 0"
        rpy="0 0 0" />
      <geometry>
        <mesh
          filename="package://Heol_humanoid/meshes/l_hip.STL" />
      </geometry>
      <material
        name="">
        <color
          rgba="0.752941176470588 0.752941176470588 0.752941176470588 1" />
      </material>
    </visual>
    <collision>
      <origin
        xyz="0 0 0"
        rpy="0 0 0" />
      <geometry>
        <mesh
          filename="package://Heol_humanoid/meshes/l_hip.STL" />
      </geometry>
    </collision>
  </link>
  <joint
    name="l_hip_y"
    type="revolute">
    <origin
      xyz="0.041652 -0.0188 0.026743"
      rpy="1.5708 0 0" />
    <parent
      link="pelvis" />
    <child
      link="l_hip" />
    <axis
      xyz="0 -1 0" />
    <limit
      lower="-2.6"
      upper="2.6"
      effort="0"
      velocity="0" />
  </joint>
  <link
    name="l_hip_motor">
    <inertial>
      <origin
        xyz="-6.01409748791117E-05 -0.00776762181170504 -0.00281391609679076"
        rpy="0 0 0" />
      <mass
        value="0.0191896773969032" />
      <inertia
        ixx="2.72857317938081E-06"
        ixy="-1.41373715165934E-08"
        ixz="1.36917622383189E-09"
        iyy="1.92531751945142E-06"
        iyz="-8.2704479615528E-08"
        izz="2.84890029696111E-06" />
    </inertial>
    <visual>
      <origin
        xyz="0 0 0"
        rpy="0 0 0" />
      <geometry>
        <mesh
          filename="package://Heol_humanoid/meshes/l_hip_motor.STL" />
      </geometry>
      <material
        name="">
        <color
          rgba="0.752941176470588 0.752941176470588 0.752941176470588 1" />
      </material>
    </visual>
    <collision>
      <origin
        xyz="0 0 0"
        rpy="0 0 0" />
      <geometry>
        <mesh
          filename="package://Heol_humanoid/meshes/l_hip_motor.STL" />
      </geometry>
    </collision>
  </link>
  <joint
    name="l_hip_motor_z"
    type="revolute">
    <origin
      xyz="-0.032 0.03 0"
      rpy="0 0 0" />
    <parent
      link="l_hip" />
    <child
      link="l_hip_motor" />
    <axis
      xyz="0 0 -1" />
    <limit
      lower="-2.6"
      upper="2.6"
      effort="0"
      velocity="0" />
  </joint>
  <link
    name="l_thigh">
    <inertial>
      <origin
        xyz="-1.10293058505628E-08 -0.0335554626566368 -5.61829485263877E-05"
        rpy="0 0 0" />
      <mass
        value="0.0205479105964943" />
      <inertia
        ixx="5.3913560500342E-06"
        ixy="-3.27768647415117E-12"
        ixz="-1.94132341312223E-11"
        iyy="2.40527757418774E-06"
        iyz="1.83746316311176E-08"
        izz="4.40730797669897E-06" />
    </inertial>
    <visual>
      <origin
        xyz="0 0 0"
        rpy="0 0 0" />
      <geometry>
        <mesh
          filename="package://Heol_humanoid/meshes/l_thigh.STL" />
      </geometry>
      <material
        name="">
        <color
          rgba="0.752941176470588 0.752941176470588 0.752941176470588 1" />
      </material>
    </visual>
    <collision>
      <origin
        xyz="0 0 0"
        rpy="0 0 0" />
      <geometry>
        <mesh
          filename="package://Heol_humanoid/meshes/l_thigh.STL" />
      </geometry>
    </collision>
  </link>
  <joint
    name="l_thigh_x"
    type="revolute">
    <origin
      xyz="0 0 -0.004"
      rpy="1.5708 0 1.5708" />
    <parent
      link="l_hip_motor" />
    <child
      link="l_thigh" />
    <axis
      xyz="0 0 -1" />
    <limit
      lower="-2.6"
      upper="2.6"
      effort="0"
      velocity="0" />
  </joint>
  <link
    name="l_knee">
    <inertial>
      <origin
        xyz="-1.07050958375599E-10 0.0225000000000239 6.77062572673748E-15"
        rpy="0 0 0" />
      <mass
        value="0.00513087567995406" />
      <inertia
        ixx="2.59601739840765E-06"
        ixy="2.71907965442483E-19"
        ixz="-2.24165647076343E-19"
        iyy="1.53262832182676E-06"
        iyz="-1.57679062737786E-21"
        izz="1.34541992010939E-06" />
    </inertial>
    <visual>
      <origin
        xyz="0 0 0"
        rpy="0 0 0" />
      <geometry>
        <mesh
          filename="package://Heol_humanoid/meshes/l_knee.STL" />
      </geometry>
      <material
        name="">
        <color
          rgba="1 1 1 1" />
      </material>
    </visual>
    <collision>
      <origin
        xyz="0 0 0"
        rpy="0 0 0" />
      <geometry>
        <mesh
          filename="package://Heol_humanoid/meshes/l_knee.STL" />
      </geometry>
    </collision>
  </link>
  <joint
    name="l_knee_x"
    type="revolute">
    <origin
      xyz="0 -0.045 0"
      rpy="-3.1416 0 0" />
    <parent
      link="l_thigh" />
    <child
      link="l_knee" />
    <axis
      xyz="0 0 1" />
    <limit
      lower="-2.6"
      upper="2.6"
      effort="0"
      velocity="0" />
  </joint>
  <link
    name="l_ankle">
    <inertial>
      <origin
        xyz="0.0124831744421506 0.00877126170541724 -0.000110062280334439"
        rpy="0 0 0" />
      <mass
        value="0.0401544687611881" />
      <inertia
        ixx="6.22341129865557E-06"
        ixy="1.13806252097558E-07"
        ixz="-3.62955227750012E-08"
        iyy="1.1354072686787E-05"
        iyz="2.17409044982687E-08"
        izz="1.39792054648314E-05" />
    </inertial>
    <visual>
      <origin
        xyz="0 0 0"
        rpy="0 0 0" />
      <geometry>
        <mesh
          filename="package://Heol_humanoid/meshes/l_ankle.STL" />
      </geometry>
      <material
        name="">
        <color
          rgba="0.752941176470588 0.752941176470588 0.752941176470588 1" />
      </material>
    </visual>
    <collision>
      <origin
        xyz="0 0 0"
        rpy="0 0 0" />
      <geometry>
        <mesh
          filename="package://Heol_humanoid/meshes/l_ankle.STL" />
      </geometry>
    </collision>
  </link>
  <joint
    name="l_ankle_x"
    type="revolute">
    <origin
      xyz="0 0.045 0"
      rpy="3.4694E-16 0 3.1416" />
    <parent
      link="l_knee" />
    <child
      link="l_ankle" />
    <axis
      xyz="0 0 1" />
    <limit
      lower="-2.6"
      upper="2.6"
      effort="0"
      velocity="0" />
  </joint>
  <link
    name="l_foot">
    <inertial>
      <origin
        xyz="-0.00642333988990457 0.0209235049680599 3.3316795269531E-05"
        rpy="0 0 0" />
      <mass
        value="0.0202605378538181" />
      <inertia
        ixx="3.14268429568422E-06"
        ixy="3.92584853218249E-07"
        ixz="-3.79765019585432E-09"
        iyy="1.48123918460857E-05"
        iyz="4.33508550117345E-10"
        izz="1.35313300236987E-05" />
    </inertial>
    <visual>
      <origin
        xyz="0 0 0"
        rpy="0 0 0" />
      <geometry>
        <mesh
          filename="package://Heol_humanoid/meshes/l_foot.STL" />
      </geometry>
      <material
        name="">
        <color
          rgba="1 1 1 1" />
      </material>
    </visual>
    <collision>
      <origin
        xyz="0 0 0"
        rpy="0 0 0" />
      <geometry>
        <mesh
          filename="package://Heol_humanoid/meshes/l_foot.STL" />
      </geometry>
    </collision>
  </link>
  <joint
    name="l_foot_y"
    type="revolute">
    <origin
      xyz="0 0 -0.0002"
      rpy="2.949E-15 0 3.1416" />
    <parent
      link="l_ankle" />
    <child
      link="l_foot" />
    <axis
      xyz="-1 0 0" />
    <limit
      lower="-2.6"
      upper="2.6"
      effort="0"
      velocity="0" />
  </joint>
  <link
    name="r_hip">
    <inertial>
      <origin
        xyz="0.0267918410324553 0.0384453640375394 0.0237344523826482"
        rpy="0 0 0" />
      <mass
        value="0.0247517363559943" />
      <inertia
        ixx="7.94295695056937E-06"
        ixy="2.1425049431127E-06"
        ixz="1.03734145559542E-06"
        iyy="4.5972428305968E-06"
        iyz="8.17998732601026E-07"
        izz="8.74766806042518E-06" />
    </inertial>
    <visual>
      <origin
        xyz="0 0 0"
        rpy="0 0 0" />
      <geometry>
        <mesh
          filename="package://Heol_humanoid/meshes/r_hip.STL" />
      </geometry>
      <material
        name="">
        <color
          rgba="0.752941176470588 0.752941176470588 0.752941176470588 1" />
      </material>
    </visual>
    <collision>
      <origin
        xyz="0 0 0"
        rpy="0 0 0" />
      <geometry>
        <mesh
          filename="package://Heol_humanoid/meshes/r_hip.STL" />
      </geometry>
    </collision>
  </link>
  <joint
    name="r_hip_y"
    type="revolute">
    <origin
      xyz="0.041652 -0.0188 0.0037433"
      rpy="1.5708 0 0" />
    <parent
      link="pelvis" />
    <child
      link="r_hip" />
    <axis
      xyz="0 -1 0" />
    <limit
      lower="-2.6"
      upper="2.6"
      effort="0"
      velocity="0" />
  </joint>
  <link
    name="r_hip_motor">
    <inertial>
      <origin
        xyz="-6.01409748823556E-05 -0.00776762181170463 -0.002813916096787"
        rpy="0 0 0" />
      <mass
        value="0.0191896773969032" />
      <inertia
        ixx="2.72857317938081E-06"
        ixy="-1.41373715165927E-08"
        ixz="1.36917622383028E-09"
        iyy="1.92531751945142E-06"
        iyz="-8.27044796155277E-08"
        izz="2.84890029696111E-06" />
    </inertial>
    <visual>
      <origin
        xyz="0 0 0"
        rpy="0 0 0" />
      <geometry>
        <mesh
          filename="package://Heol_humanoid/meshes/r_hip_motor.STL" />
      </geometry>
      <material
        name="">
        <color
          rgba="0.752941176470588 0.752941176470588 0.752941176470588 1" />
      </material>
    </visual>
    <collision>
      <origin
        xyz="0 0 0"
        rpy="0 0 0" />
      <geometry>
        <mesh
          filename="package://Heol_humanoid/meshes/r_hip_motor.STL" />
      </geometry>
    </collision>
  </link>
  <joint
    name="r_hip_motor_z"
    type="revolute">
    <origin
      xyz="0.032 0.053 0"
      rpy="0 0 0" />
    <parent
      link="r_hip" />
    <child
      link="r_hip_motor" />
    <axis
      xyz="0 0 -1" />
    <limit
      lower="-2.6"
      upper="2.6"
      effort="0"
      velocity="0" />
  </joint>
  <link
    name="r_thigh">
    <inertial>
      <origin
        xyz="-8.92757523462961E-09 -0.0335554544923747 -5.61776243046541E-05"
        rpy="0 0 0" />
      <mass
        value="0.0205479194607194" />
      <inertia
        ixx="5.39136068968386E-06"
        ixy="-2.4762091999764E-12"
        ixz="-1.88429697745015E-11"
        iyy="2.40527919108636E-06"
        iyz="1.83766538429762E-08"
        izz="4.4073113555423E-06" />
    </inertial>
    <visual>
      <origin
        xyz="0 0 0"
        rpy="0 0 0" />
      <geometry>
        <mesh
          filename="package://Heol_humanoid/meshes/r_thigh.STL" />
      </geometry>
      <material
        name="">
        <color
          rgba="0.752941176470588 0.752941176470588 0.752941176470588 1" />
      </material>
    </visual>
    <collision>
      <origin
        xyz="0 0 0"
        rpy="0 0 0" />
      <geometry>
        <mesh
          filename="package://Heol_humanoid/meshes/r_thigh.STL" />
      </geometry>
    </collision>
  </link>
  <joint
    name="r_thigh_x"
    type="revolute">
    <origin
      xyz="0 0 -0.004"
      rpy="1.5708 0 1.5708" />
    <parent
      link="r_hip_motor" />
    <child
      link="r_thigh" />
    <axis
      xyz="0 0 -1" />
    <limit
      lower="-2.6"
      upper="2.6"
      effort="0"
      velocity="0" />
  </joint>
  <link
    name="r_knee">
    <inertial>
      <origin
        xyz="-1.07040286356774E-10 -0.0225000000000002 -3.7470027081099E-16"
        rpy="0 0 0" />
      <mass
        value="0.00513087567995406" />
      <inertia
        ixx="2.59601739840765E-06"
        ixy="-1.79523246211754E-19"
        ixz="6.7046742654957E-23"
        iyy="1.53262832182676E-06"
        iyz="-2.65745957125253E-21"
        izz="1.34541992010939E-06" />
    </inertial>
    <visual>
      <origin
        xyz="0 0 0"
        rpy="0 0 0" />
      <geometry>
        <mesh
          filename="package://Heol_humanoid/meshes/r_knee.STL" />
      </geometry>
      <material
        name="">
        <color
          rgba="1 1 1 1" />
      </material>
    </visual>
    <collision>
      <origin
        xyz="0 0 0"
        rpy="0 0 0" />
      <geometry>
        <mesh
          filename="package://Heol_humanoid/meshes/r_knee.STL" />
      </geometry>
    </collision>
  </link>
  <joint
    name="r_knee_x"
    type="revolute">
    <origin
      xyz="0 -0.045 0"
      rpy="1.3878E-15 1.3878E-15 1.3482E-29" />
    <parent
      link="r_thigh" />
    <child
      link="r_knee" />
    <axis
      xyz="0 0 -1" />
    <limit
      lower="-2.6"
      upper="2.6"
      effort="0"
      velocity="0" />
  </joint>
  <link
    name="r_ankle">
    <inertial>
      <origin
        xyz="0.0124831744421376 0.0087712617054444 -0.000110062280338594"
        rpy="0 0 0" />
      <mass
        value="0.040154468761188" />
      <inertia
        ixx="6.22341129865557E-06"
        ixy="1.13806252097996E-07"
        ixz="-3.62955227736119E-08"
        iyy="1.1354072686787E-05"
        iyz="2.17409044982815E-08"
        izz="1.39792054648314E-05" />
    </inertial>
    <visual>
      <origin
        xyz="0 0 0"
        rpy="0 0 0" />
      <geometry>
        <mesh
          filename="package://Heol_humanoid/meshes/r_ankle.STL" />
      </geometry>
      <material
        name="">
        <color
          rgba="0.752941176470588 0.752941176470588 0.752941176470588 1" />
      </material>
    </visual>
    <collision>
      <origin
        xyz="0 0 0"
        rpy="0 0 0" />
      <geometry>
        <mesh
          filename="package://Heol_humanoid/meshes/r_ankle.STL" />
      </geometry>
    </collision>
  </link>
  <joint
    name="r_ankle_x"
    type="revolute">
    <origin
      xyz="0 -0.045 0"
      rpy="-3.1416 1.3878E-15 3.1416" />
    <parent
      link="r_knee" />
    <child
      link="r_ankle" />
    <axis
      xyz="0 0 1" />
    <limit
      lower="-2.6"
      upper="2.6"
      effort="0"
      velocity="0" />
  </joint>
  <link
    name="r_foot">
    <inertial>
      <origin
        xyz="-0.0064233398899067 0.020923504968057 3.33167952701469E-05"
        rpy="0 0 0" />
      <mass
        value="0.0202605378538181" />
      <inertia
        ixx="3.14268429568432E-06"
        ixy="3.92584853219292E-07"
        ixz="-3.79765019772886E-09"
        iyy="1.48123918460857E-05"
        iyz="4.33508550050083E-10"
        izz="1.35313300236987E-05" />
    </inertial>
    <visual>
      <origin
        xyz="0 0 0"
        rpy="0 0 0" />
      <geometry>
        <mesh
          filename="package://Heol_humanoid/meshes/r_foot.STL" />
      </geometry>
      <material
        name="">
        <color
          rgba="1 1 1 1" />
      </material>
    </visual>
    <collision>
      <origin
        xyz="0 0 0"
        rpy="0 0 0" />
      <geometry>
        <mesh
          filename="package://Heol_humanoid/meshes/r_foot.STL" />
      </geometry>
    </collision>
  </link>
  <joint
    name="r_foot_y"
    type="revolute">
    <origin
      xyz="0 0 -0.0002"
      rpy="1.3878E-15 8.3267E-15 3.1416" />
    <parent
      link="r_ankle" />
    <child
      link="r_foot" />
    <axis
      xyz="-1 0 0" />
    <limit
      lower="-2.6"
      upper="2.6"
      effort="0"
      velocity="0" />
  </joint>
  <link
    name="spine">
    <inertial>
      <origin
        xyz="-2.90372275777162E-05 0.0147514539929462 0.00718055086358074"
        rpy="0 0 0" />
      <mass
        value="0.0236192598262425" />
      <inertia
        ixx="4.62186731278599E-06"
        ixy="-3.679490125193E-10"
        ixz="1.93443338679822E-08"
        iyy="4.35953212647662E-06"
        iyz="-3.88430201428807E-08"
        izz="2.68872368915042E-06" />
    </inertial>
    <visual>
      <origin
        xyz="0 0 0"
        rpy="0 0 0" />
      <geometry>
        <mesh
          filename="package://Heol_humanoid/meshes/spine.STL" />
      </geometry>
      <material
        name="">
        <color
          rgba="0.752941176470588 0.752941176470588 0.752941176470588 1" />
      </material>
    </visual>
    <collision>
      <origin
        xyz="0 0 0"
        rpy="0 0 0" />
      <geometry>
        <mesh
          filename="package://Heol_humanoid/meshes/spine.STL" />
      </geometry>
    </collision>
  </link>
  <joint
    name="spine_z"
    type="revolute">
    <origin
      xyz="0.041652 -0.0728 0.058743"
      rpy="3.1416 0 0" />
    <parent
      link="pelvis" />
    <child
      link="spine" />
    <axis
      xyz="0 -1 0" />
    <limit
      lower="-2.6"
      upper="2.6"
      effort="0"
      velocity="0" />
  </joint>
  <link
    name="chest">
    <inertial>
      <origin
        xyz="0.00020921714160152 -0.0105992948545036 0.0552607808872334"
        rpy="0 0 0" />
      <mass
        value="0.0820076699949507" />
      <inertia
        ixx="2.88162299882089E-05"
        ixy="1.06916662819482E-07"
        ixz="-1.68102798653458E-11"
        iyy="6.21578508234131E-05"
        iyz="-2.54269144988347E-06"
        izz="5.38555817387205E-05" />
    </inertial>
    <visual>
      <origin
        xyz="0 0 0"
        rpy="0 0 0" />
      <geometry>
        <mesh
          filename="package://Heol_humanoid/meshes/chest.STL" />
      </geometry>
      <material
        name="">
        <color
          rgba="0.752941176470588 0.752941176470588 0.752941176470588 1" />
      </material>
    </visual>
    <collision>
      <origin
        xyz="0 0 0"
        rpy="0 0 0" />
      <geometry>
        <mesh
          filename="package://Heol_humanoid/meshes/chest.STL" />
      </geometry>
    </collision>
  </link>
  <joint
    name="chest_x"
    type="revolute">
    <origin
      xyz="0 0.015 0"
      rpy="-1.5708 0 0" />
    <parent
      link="spine" />
    <child
      link="chest" />
    <axis
      xyz="-1 0 0" />
    <limit
      lower="-2.6"
      upper="2.6"
      effort="0"
      velocity="0" />
  </joint>
  <link
    name="l_shoulder">
    <inertial>
      <origin
        xyz="0.00738135253471293 0.009975713146232 -0.00170181446250049"
        rpy="0 0 0" />
      <mass
        value="0.0033436832656123" />
      <inertia
        ixx="7.55281237041108E-07"
        ixy="2.87345125280383E-15"
        ixz="1.181387037147E-09"
        iyy="8.36222428966545E-07"
        iyz="-1.74492357212462E-16"
        izz="2.71216334387687E-07" />
    </inertial>
    <visual>
      <origin
        xyz="0 0 0"
        rpy="0 0 0" />
      <geometry>
        <mesh
          filename="package://Heol_humanoid/meshes/l_shoulder.STL" />
      </geometry>
      <material
        name="">
        <color
          rgba="1 1 1 1" />
      </material>
    </visual>
    <collision>
      <origin
        xyz="0 0 0"
        rpy="0 0 0" />
      <geometry>
        <mesh
          filename="package://Heol_humanoid/meshes/l_shoulder.STL" />
      </geometry>
    </collision>
  </link>
  <joint
    name="l_shoulder_x"
    type="revolute">
    <origin
      xyz="-0.0436 -0.00015034 0.051"
      rpy="1.5708 -1.3E-29 3.1416" />
    <parent
      link="chest" />
    <child
      link="l_shoulder" />
    <axis
      xyz="1 0 0" />
    <limit
      lower="-2.6"
      upper="2.6"
      effort="0"
      velocity="0" />
  </joint>
  <link
    name="l_shoulder_motor">
    <inertial>
      <origin
        xyz="-1.23621125059613E-05 -0.01288308513281 -0.00498956125927229"
        rpy="0 0 0" />
      <mass
        value="0.0337180938758863" />
      <inertia
        ixx="1.3841219960724E-05"
        ixy="4.4423812928381E-09"
        ixz="3.61149886689666E-09"
        iyy="3.92279038864261E-06"
        iyz="1.82027066261676E-06"
        izz="1.23612082652879E-05" />
    </inertial>
    <visual>
      <origin
        xyz="0 0 0"
        rpy="0 0 0" />
      <geometry>
        <mesh
          filename="package://Heol_humanoid/meshes/l_shoulder_motor.STL" />
      </geometry>
      <material
        name="">
        <color
          rgba="0.752941176470588 0.752941176470588 0.752941176470588 1" />
      </material>
    </visual>
    <collision>
      <origin
        xyz="0 0 0"
        rpy="0 0 0" />
      <geometry>
        <mesh
          filename="package://Heol_humanoid/meshes/l_shoulder_motor.STL" />
      </geometry>
    </collision>
  </link>
  <joint
    name="l_shoulder_motor_y"
    type="revolute">
    <origin
      xyz="0.018 0 0"
      rpy="0 -7.8886E-31 0" />
    <parent
      link="l_shoulder" />
    <child
      link="l_shoulder_motor" />
    <axis
      xyz="0 0 -1" />
    <limit
      lower="-2.6"
      upper="2.6"
      effort="0"
      velocity="0" />
  </joint>
  <link
    name="l_upper_arm">
    <inertial>
      <origin
        xyz="-0.00258999199198134 4.39981210783452E-06 0.00172771895751343"
        rpy="0 0 0" />
      <mass
        value="0.00334368326578746" />
      <inertia
        ixx="7.55284120272145E-07"
        ixy="-2.87671853332062E-15"
        ixz="3.86783789643827E-16"
        iyy="8.36222428969736E-07"
        iyz="-2.53584885031747E-16"
        izz="2.71213451173539E-07" />
    </inertial>
    <visual>
      <origin
        xyz="0 0 0"
        rpy="0 0 0" />
      <geometry>
        <mesh
          filename="package://Heol_humanoid/meshes/l_upper_arm.STL" />
      </geometry>
      <material
        name="">
        <color
          rgba="1 1 1 1" />
      </material>
    </visual>
    <collision>
      <origin
        xyz="0 0 0"
        rpy="0 0 0" />
      <geometry>
        <mesh
          filename="package://Heol_humanoid/meshes/l_upper_arm.STL" />
      </geometry>
    </collision>
  </link>
  <joint
    name="l_upper_arm_z"
    type="revolute">
    <origin
      xyz="0 -0.054 0"
      rpy="3.1416 2.0817E-15 -1.5708" />
    <parent
      link="l_shoulder_motor" />
    <child
      link="l_upper_arm" />
    <axis
      xyz="1 0 0" />
    <limit
      lower="-2.6"
      upper="2.6"
      effort="0"
      velocity="0" />
  </joint>
  <link
    name="l_forearm">
    <inertial>
      <origin
        xyz="0.00275878255562566 -0.00985811408174951 -0.00151285287447106"
        rpy="0 0 0" />
      <mass
        value="0.0257657351354794" />
      <inertia
        ixx="1.28753735465766E-05"
        ixy="-2.09824525987835E-06"
        ixz="-4.15371891487782E-08"
        iyy="2.70910011838058E-06"
        iyz="-4.05301232333935E-08"
        izz="1.28181627224906E-05" />
    </inertial>
    <visual>
      <origin
        xyz="0 0 0"
        rpy="0 0 0" />
      <geometry>
        <mesh
          filename="package://Heol_humanoid/meshes/l_forearm.STL" />
      </geometry>
      <material
        name="">
        <color
          rgba="0.752941176470588 0.752941176470588 0.752941176470588 1" />
      </material>
    </visual>
    <collision>
      <origin
        xyz="0 0 0"
        rpy="0 0 0" />
      <geometry>
        <mesh
          filename="package://Heol_humanoid/meshes/l_forearm.STL" />
      </geometry>
    </collision>
  </link>
  <joint
    name="l_forearm_y"
    type="revolute">
    <origin
      xyz="0.018 0 0"
      rpy="3.1416 1.1102E-14 -1.5708" />
    <parent
      link="l_upper_arm" />
    <child
      link="l_forearm" />
    <axis
      xyz="0 0 -1" />
    <limit
      lower="-2.6"
      upper="2.6"
      effort="0"
      velocity="0" />
  </joint>
  <link
    name="r_shoulder">
    <inertial>
      <origin
        xyz="0.00747429715166746 -0.00997549115327001 -0.00172772478548004"
        rpy="0 0 0" />
      <mass
        value="0.00334368326561429" />
      <inertia
        ixx="7.55284120264201E-07"
        ixy="2.87394548411926E-15"
        ixz="7.07070234950382E-16"
        iyy="8.3622242896673E-07"
        iyz="-2.93903791676957E-16"
        izz="2.7121345116496E-07" />
    </inertial>
    <visual>
      <origin
        xyz="0 0 0"
        rpy="0 0 0" />
      <geometry>
        <mesh
          filename="package://Heol_humanoid/meshes/r_shoulder.STL" />
      </geometry>
      <material
        name="">
        <color
          rgba="1 1 1 1" />
      </material>
    </visual>
    <collision>
      <origin
        xyz="0 0 0"
        rpy="0 0 0" />
      <geometry>
        <mesh
          filename="package://Heol_humanoid/meshes/r_shoulder.STL" />
      </geometry>
    </collision>
  </link>
  <joint
    name="r_shoulder_x"
    type="revolute">
    <origin
      xyz="0.043911 0.00010717 0.051"
      rpy="-1.5708 -1.6935E-18 0.0024405" />
    <parent
      link="chest" />
    <child
      link="r_shoulder" />
    <axis
      xyz="-1 0 0" />
    <limit
      lower="-2.6"
      upper="2.6"
      effort="0"
      velocity="0" />
  </joint>
  <link
    name="r_shoulder_motor">
    <inertial>
      <origin
        xyz="-1.42227148114404E-09 -0.0128833066950635 -0.00498957682104674"
        rpy="0 0 0" />
      <mass
        value="0.03371809385647" />
      <inertia
        ixx="1.3841228759395E-05"
        ixy="-6.61891241280995E-14"
        ixz="-5.55259480231669E-13"
        iyy="3.92279038814914E-06"
        iyz="1.82027608763325E-06"
        izz="1.23611994388016E-05" />
    </inertial>
    <visual>
      <origin
        xyz="0 0 0"
        rpy="0 0 0" />
      <geometry>
        <mesh
          filename="package://Heol_humanoid/meshes/r_shoulder_motor.STL" />
      </geometry>
      <material
        name="">
        <color
          rgba="0.752941176470588 0.752941176470588 0.752941176470588 1" />
      </material>
    </visual>
    <collision>
      <origin
        xyz="0 0 0"
        rpy="0 0 0" />
      <geometry>
        <mesh
          filename="package://Heol_humanoid/meshes/r_shoulder_motor.STL" />
      </geometry>
    </collision>
  </link>
  <joint
    name="r_shoulder_motor_y"
    type="revolute">
    <origin
      xyz="0.018089 0 0"
      rpy="-9.8608E-32 4.3368E-19 3.1416" />
    <parent
      link="r_shoulder" />
    <child
      link="r_shoulder_motor" />
    <axis
      xyz="0 0 -1" />
    <limit
      lower="-2.6"
      upper="2.6"
      effort="0"
      velocity="0" />
  </joint>
  <link
    name="r_upper_arm">
    <inertial>
      <origin
        xyz="-0.00258977041425777 4.2163669399381E-06 0.00172771966128194"
        rpy="0 0 0" />
      <mass
        value="0.00334368326578746" />
      <inertia
        ixx="7.55284120272143E-07"
        ixy="-2.87334423519207E-15"
        ixz="2.88458002796294E-16"
        iyy="8.36222428969734E-07"
        iyz="-2.87796451805079E-16"
        izz="2.71213451173539E-07" />
    </inertial>
    <visual>
      <origin
        xyz="0 0 0"
        rpy="0 0 0" />
      <geometry>
        <mesh
          filename="package://Heol_humanoid/meshes/r_upper_arm.STL" />
      </geometry>
      <material
        name="">
        <color
          rgba="1 1 1 1" />
      </material>
    </visual>
    <collision>
      <origin
        xyz="0 0 0"
        rpy="0 0 0" />
      <geometry>
        <mesh
          filename="package://Heol_humanoid/meshes/r_upper_arm.STL" />
      </geometry>
    </collision>
  </link>
  <joint
    name="r_upper_arm_z"
    type="revolute">
    <origin
      xyz="0 -0.054 0"
      rpy="-3.1392 6.9389E-16 -1.5708" />
    <parent
      link="r_shoulder_motor" />
    <child
      link="r_upper_arm" />
    <axis
      xyz="1 0 0" />
    <limit
      lower="-2.6"
      upper="2.6"
      effort="0"
      velocity="0" />
  </joint>
  <link
    name="r_forearm">
    <inertial>
      <origin
        xyz="-0.00276742190731027 -0.00985840898463672 -0.00151302525358472"
        rpy="0 0 0" />
      <mass
        value="0.0257657889801188" />
      <inertia
        ixx="1.28754577391755E-05"
        ixy="2.09826471210379E-06"
        ixz="4.15636504905883E-08"
        iyy="2.7091088250933E-06"
        iyz="-4.0346750212717E-08"
        izz="1.28182439095505E-05" />
    </inertial>
    <visual>
      <origin
        xyz="0 0 0"
        rpy="0 0 0" />
      <geometry>
        <mesh
          filename="package://Heol_humanoid/meshes/r_forearm.STL" />
      </geometry>
      <material
        name="">
        <color
          rgba="0.752941176470588 0.752941176470588 0.752941176470588 1" />
      </material>
    </visual>
    <collision>
      <origin
        xyz="0 0 0"
        rpy="0 0 0" />
      <geometry>
        <mesh
          filename="package://Heol_humanoid/meshes/r_forearm.STL" />
      </geometry>
    </collision>
  </link>
  <joint
    name="r_forearm_y"
    type="revolute">
    <origin
      xyz="0.018 0 0"
      rpy="-3.1416 2.0817E-14 -1.5708" />
    <parent
      link="r_upper_arm" />
    <child
      link="r_forearm" />
    <axis
      xyz="0 0 -1" />
    <limit
      lower="-2.6"
      upper="2.6"
      effort="0"
      velocity="0" />
  </joint>
  <link
    name="head">
    <inertial>
      <origin
        xyz="-2.75816754688463E-06 0.0382668888856673 0.00655496591415367"
        rpy="0 0 0" />
      <mass
        value="0.023415330566188" />
      <inertia
        ixx="1.9436552244627E-05"
        ixy="-5.90454549538582E-10"
        ixz="9.03662837892086E-11"
        iyy="1.81703660884301E-05"
        iyz="1.67171458454172E-06"
        izz="1.80994363748861E-05" />
    </inertial>
    <visual>
      <origin
        xyz="0 0 0"
        rpy="0 0 0" />
      <geometry>
        <mesh
          filename="package://Heol_humanoid/meshes/head.STL" />
      </geometry>
      <material
        name="">
        <color
          rgba="0.752941176470588 0.752941176470588 0.752941176470588 1" />
      </material>
    </visual>
    <collision>
      <origin
        xyz="0 0 0"
        rpy="0 0 0" />
      <geometry>
        <mesh
          filename="package://Heol_humanoid/meshes/head.STL" />
      </geometry>
    </collision>
  </link>
  <joint
    name="head_z"
    type="revolute">
    <origin
      xyz="0.00020517 -0.0021163 0.076016"
      rpy="1.5967 6.4765E-05 -6.3111E-05" />
    <parent
      link="chest" />
    <child
      link="head" />
    <axis
      xyz="0 -1 0" />
    <limit
      lower="-2.6"
      upper="2.6"
      effort="0"
      velocity="0" />
  </joint>
</robot>