<robot
  name="Heol_humanoid">
  <link
    name="pelvis">
    <inertial>
      <origin
        xyz="0.0410669745819321 -0.0379110717402652 0.0421828125034158"
        rpy="0 0 0" />
      <mass
        value="0.0572942260553945" />
      <inertia
        ixx="3.65121025707978E-05"
        ixy="2.99007836945978E-07"
        ixz="4.85882286230636E-07"
        iyy="2.12489482613664E-05"
        iyz="-3.35587468839814E-06"
        izz="2.000430429396E-05" />
    </inertial>
    <visual>
      <origin
        xyz="0 0 0"
        rpy="0 0 0" />
      <geometry>
        <mesh
          filename="package://meshes/pelvis_visual.STL" /></geometry><material
        name="">
        <color
          rgba="0.752941176470588 0.752941176470588 0.752941176470588 1" />
      </material>
    </visual>
    <collision>
      <origin
        xyz="0 0 0"
        rpy="0 0 0" />
      <geometry>
        <mesh
          filename="package://meshes/pelvis_respondable.STL" /></geometry></collision>
  </link>
  <link
    name="l_hip">
    <inertial>
      <origin
        xyz="-0.0270835640140282 0.0231158477663268 0.0237291455019634"
        rpy="0 0 0" />
      <mass
        value="0.0238887563110607" />
      <inertia
        ixx="5.49518226158328E-06"
        ixy="6.82907038074934E-07"
        ixz="-1.00493628454709E-06"
        iyy="4.44318183140713E-06"
        iyz="-4.31099554695611E-07"
        izz="6.27728430763791E-06" />
    </inertial>
    <visual>
      <origin
        xyz="0 0 0"
        rpy="0 0 0" />
      <geometry>
        <mesh
          filename="package://meshes/l_hip_visual.STL" /></geometry><material
        name="">
        <color
          rgba="0.752941176470588 0.752941176470588 0.752941176470588 1" />
      </material>
    </visual>
    <collision>
      <origin
        xyz="0 0 0"
        rpy="0 0 0" />
      <geometry>
        <mesh
          filename="package://meshes/l_hip_respondable.STL" /></geometry></collision>
  </link>
  <joint
    name="l_hip_y"
    type="revolute">
    <origin
      xyz="0.041652 -0.0188 0.026743"
      rpy="1.5708 0 0" />
    <parent
      link="pelvis" />
    <child
      link="l_hip" />
    <axis
      xyz="0 -1 0" />
    <limit
      lower="-2.6"
      upper="2.6"
      effort="3.1" velocity="7.0" />
  </joint>
  <link
    name="l_hip_motor">
    <inertial>
      <origin
        xyz="-6.01409748791099E-05 -0.00776762181170503 -0.00281391609679076"
        rpy="0 0 0" />
      <mass
        value="0.0191896773969032" />
      <inertia
        ixx="2.72857317938081E-06"
        ixy="-1.41373715165934E-08"
        ixz="1.36917622383186E-09"
        iyy="1.92531751945142E-06"
        iyz="-8.27044796155279E-08"
        izz="2.84890029696111E-06" />
    </inertial>
    <visual>
      <origin
        xyz="0 0 0"
        rpy="0 0 0" />
      <geometry>
        <mesh
          filename="package://meshes/l_hip_motor_visual.STL" /></geometry><material
        name="">
        <color
          rgba="0.752941176470588 0.752941176470588 0.752941176470588 1" />
      </material>
    </visual>
    <collision>
      <origin
        xyz="0 0 0"
        rpy="0 0 0" />
      <geometry>
        <mesh
          filename="package://meshes/l_hip_motor_respondable.STL" /></geometry></collision>
  </link>
  <joint
    name="l_hip_motor_z"
    type="revolute">
    <origin
      xyz="-0.032 0.03 0"
      rpy="0 0 0" />
    <parent
      link="l_hip" />
    <child
      link="l_hip_motor" />
    <axis
      xyz="0 0 -1" />
    <limit
      lower="-2.6"
      upper="2.6"
      effort="3.1" velocity="7.0" />
  </joint>
  <link
    name="l_thigh">
    <inertial>
      <origin
        xyz="-1.10293058575017E-08 -0.0335554626566368 -5.61829485263877E-05"
        rpy="0 0 0" />
      <mass
        value="0.0205479105964943" />
      <inertia
        ixx="5.3913560500342E-06"
        ixy="-3.2776864735829E-12"
        ixz="-1.94132341312519E-11"
        iyy="2.40527757418774E-06"
        iyz="1.8374631631118E-08"
        izz="4.40730797669897E-06" />
    </inertial>
    <visual>
      <origin
        xyz="0 0 0"
        rpy="0 0 0" />
      <geometry>
        <mesh
          filename="package://meshes/l_thigh_visual.STL" /></geometry><material
        name="">
        <color
          rgba="0.752941176470588 0.752941176470588 0.752941176470588 1" />
      </material>
    </visual>
    <collision>
      <origin
        xyz="0 0 0"
        rpy="0 0 0" />
      <geometry>
        <mesh
          filename="package://meshes/l_thigh_respondable.STL" /></geometry></collision>
  </link>
  <joint
    name="l_thigh_x"
    type="revolute">
    <origin
      xyz="0 0 -0.004"
      rpy="1.5708 0 1.5708" />
    <parent
      link="l_hip_motor" />
    <child
      link="l_thigh" />
    <axis
      xyz="0 0 -1" />
    <limit
      lower="-2.6"
      upper="2.6"
      effort="3.1" velocity="7.0" />
  </joint>
  <link
    name="l_knee">
    <inertial>
      <origin
        xyz="-1.07050958375599E-10 0.0225000000000239 6.77582989716541E-15"
        rpy="0 0 0" />
      <mass
        value="0.00513087567995406" />
      <inertia
        ixx="2.59601739840765E-06"
        ixy="2.71892405350454E-19"
        ixz="-2.23883722831456E-19"
        iyy="1.53262832182676E-06"
        iyz="-1.87471138011425E-21"
        izz="1.34541992010939E-06" />
    </inertial>
    <visual>
      <origin
        xyz="0 0 0"
        rpy="0 0 0" />
      <geometry>
        <mesh
          filename="package://meshes/l_knee_visual.STL" /></geometry><material
        name="">
        <color
          rgba="1 1 1 1" />
      </material>
    </visual>
    <collision>
      <origin
        xyz="0 0 0"
        rpy="0 0 0" />
      <geometry>
        <mesh
          filename="package://meshes/l_knee_respondable.STL" /></geometry></collision>
  </link>
  <joint
    name="l_knee_x"
    type="revolute">
    <origin
      xyz="0 -0.045 0"
      rpy="-3.1416 0 0" />
    <parent
      link="l_thigh" />
    <child
      link="l_knee" />
    <axis
      xyz="0 0 1" />
    <limit
      lower="-2.6"
      upper="2.6"
      effort="3.1" velocity="7.0" />
  </joint>
  <link
    name="l_ankle">
    <inertial>
      <origin
        xyz="0.0124831744421506 0.0087712617054173 -0.000110062280334441"
        rpy="0 0 0" />
      <mass
        value="0.0401544687611881" />
      <inertia
        ixx="6.22341129865557E-06"
        ixy="1.13806252097558E-07"
        ixz="-3.62955227750015E-08"
        iyy="1.1354072686787E-05"
        iyz="2.17409044982688E-08"
        izz="1.39792054648314E-05" />
    </inertial>
    <visual>
      <origin
        xyz="0 0 0"
        rpy="0 0 0" />
      <geometry>
        <mesh
          filename="package://meshes/l_ankle_visual.STL" /></geometry><material
        name="">
        <color
          rgba="0.752941176470588 0.752941176470588 0.752941176470588 1" />
      </material>
    </visual>
    <collision>
      <origin
        xyz="0 0 0"
        rpy="0 0 0" />
      <geometry>
        <mesh
          filename="package://meshes/l_ankle_respondable.STL" /></geometry></collision>
  </link>
  <joint
    name="l_ankle_x"
    type="revolute">
    <origin
      xyz="0 0.045 0"
      rpy="3.4694E-16 0 3.1416" />
    <parent
      link="l_knee" />
    <child
      link="l_ankle" />
    <axis
      xyz="0 0 1" />
    <limit
      lower="-2.6"
      upper="2.6"
      effort="3.1" velocity="7.0" />
  </joint>
  <link
    name="l_foot">
    <inertial>
      <origin
        xyz="-0.00642333988990457 0.0209235049680599 3.33167952695258E-05"
        rpy="0 0 0" />
      <mass
        value="0.0202605378538181" />
      <inertia
        ixx="3.14268429568421E-06"
        ixy="3.92584853218249E-07"
        ixz="-3.79765019585422E-09"
        iyy="1.48123918460857E-05"
        iyz="4.33508550120775E-10"
        izz="1.35313300236987E-05" />
    </inertial>
    <visual>
      <origin
        xyz="0 0 0"
        rpy="0 0 0" />
      <geometry>
        <mesh
          filename="package://meshes/l_foot_visual.STL" /></geometry><material
        name="">
        <color
          rgba="1 1 1 1" />
      </material>
    </visual>
    <collision>
      <origin
        xyz="0 0 0"
        rpy="0 0 0" />
      <geometry>
        <mesh
          filename="package://meshes/l_foot_respondable.STL" /></geometry></collision>
  </link>
  <joint
    name="l_foot_y"
    type="revolute">
    <origin
      xyz="0 0 -0.0002"
      rpy="2.949E-15 0 3.1416" />
    <parent
      link="l_ankle" />
    <child
      link="l_foot" />
    <axis
      xyz="-1 0 0" />
    <limit
      lower="-2.6"
      upper="2.6"
      effort="3.1" velocity="7.0" />
  </joint>
  <link
    name="r_hip">
    <inertial>
      <origin
        xyz="0.0267918410324552 0.0384453640375394 0.0237344523826482"
        rpy="0 0 0" />
      <mass
        value="0.0247517363559943" />
      <inertia
        ixx="7.94295695056937E-06"
        ixy="2.1425049431127E-06"
        ixz="1.03734145559542E-06"
        iyy="4.5972428305968E-06"
        iyz="8.17998732601026E-07"
        izz="8.74766806042518E-06" />
    </inertial>
    <visual>
      <origin
        xyz="0 0 0"
        rpy="0 0 0" />
      <geometry>
        <mesh
          filename="package://meshes/r_hip_visual.STL" /></geometry><material
        name="">
        <color
          rgba="0.752941176470588 0.752941176470588 0.752941176470588 1" />
      </material>
    </visual>
    <collision>
      <origin
        xyz="0 0 0"
        rpy="0 0 0" />
      <geometry>
        <mesh
          filename="package://meshes/r_hip_respondable.STL" /></geometry></collision>
  </link>
  <joint
    name="r_hip_y"
    type="revolute">
    <origin
      xyz="0.041652 -0.0188 0.0037433"
      rpy="1.5708 0 0" />
    <parent
      link="pelvis" />
    <child
      link="r_hip" />
    <axis
      xyz="0 -1 0" />
    <limit
      lower="-2.6"
      upper="2.6"
      effort="3.1" velocity="7.0" />
  </joint>
  <link
    name="r_hip_motor">
    <inertial>
      <origin
        xyz="-6.01409748823833E-05 -0.00776762181170463 -0.00281391609678699"
        rpy="0 0 0" />
      <mass
        value="0.0191896773969032" />
      <inertia
        ixx="2.72857317938081E-06"
        ixy="-1.41373715165928E-08"
        ixz="1.36917622383047E-09"
        iyy="1.92531751945142E-06"
        iyz="-8.27044796155278E-08"
        izz="2.84890029696111E-06" />
    </inertial>
    <visual>
      <origin
        xyz="0 0 0"
        rpy="0 0 0" />
      <geometry>
        <mesh
          filename="package://meshes/r_hip_motor_visual.STL" /></geometry><material
        name="">
        <color
          rgba="0.752941176470588 0.752941176470588 0.752941176470588 1" />
      </material>
    </visual>
    <collision>
      <origin
        xyz="0 0 0"
        rpy="0 0 0" />
      <geometry>
        <mesh
          filename="package://meshes/r_hip_motor_respondable.STL" /></geometry></collision>
  </link>
  <joint
    name="r_hip_motor_z"
    type="revolute">
    <origin
      xyz="0.032 0.053 0"
      rpy="0 0 0" />
    <parent
      link="r_hip" />
    <child
      link="r_hip_motor" />
    <axis
      xyz="0 0 -1" />
    <limit
      lower="-2.6"
      upper="2.6"
      effort="3.1" velocity="7.0" />
  </joint>
  <link
    name="r_thigh">
    <inertial>
      <origin
        xyz="-8.92757522075183E-09 -0.0335554544923748 -5.6177624304668E-05"
        rpy="0 0 0" />
      <mass
        value="0.0205479194607194" />
      <inertia
        ixx="5.39136068968386E-06"
        ixy="-2.47620919978419E-12"
        ixz="-1.88429697743176E-11"
        iyy="2.40527919108636E-06"
        iyz="1.83766538429754E-08"
        izz="4.4073113555423E-06" />
    </inertial>
    <visual>
      <origin
        xyz="0 0 0"
        rpy="0 0 0" />
      <geometry>
        <mesh
          filename="package://meshes/r_thigh_visual.STL" /></geometry><material
        name="">
        <color
          rgba="0.752941176470588 0.752941176470588 0.752941176470588 1" />
      </material>
    </visual>
    <collision>
      <origin
        xyz="0 0 0"
        rpy="0 0 0" />
      <geometry>
        <mesh
          filename="package://meshes/r_thigh_respondable.STL" /></geometry></collision>
  </link>
  <joint
    name="r_thigh_x"
    type="revolute">
    <origin
      xyz="0 0 -0.004"
      rpy="1.5708 0 1.5708" />
    <parent
      link="r_hip_motor" />
    <child
      link="r_thigh" />
    <axis
      xyz="0 0 -1" />
    <limit
      lower="-2.6"
      upper="2.6"
      effort="3.1" velocity="7.0" />
  </joint>
  <link
    name="r_knee">
    <inertial>
      <origin
        xyz="-1.07040286356774E-10 -0.0225000000000002 -3.7470027081099E-16"
        rpy="0 0 0" />
      <mass
        value="0.00513087567995406" />
      <inertia
        ixx="2.59601739840765E-06"
        ixy="-1.79527148703891E-19"
        ixz="6.32730151001067E-23"
        iyy="1.53262832182676E-06"
        iyz="-1.48834126513182E-21"
        izz="1.34541992010939E-06" />
    </inertial>
    <visual>
      <origin
        xyz="0 0 0"
        rpy="0 0 0" />
      <geometry>
        <mesh
          filename="package://meshes/r_knee_visual.STL" /></geometry><material
        name="">
        <color
          rgba="1 1 1 1" />
      </material>
    </visual>
    <collision>
      <origin
        xyz="0 0 0"
        rpy="0 0 0" />
      <geometry>
        <mesh
          filename="package://meshes/r_knee_respondable.STL" /></geometry></collision>
  </link>
  <joint
    name="r_knee_x"
    type="revolute">
    <origin
      xyz="0 -0.045 0"
      rpy="1.3878E-15 1.3878E-15 1.3482E-29" />
    <parent
      link="r_thigh" />
    <child
      link="r_knee" />
    <axis
      xyz="0 0 -1" />
    <limit
      lower="-2.6"
      upper="2.6"
      effort="3.1" velocity="7.0" />
  </joint>
  <link
    name="r_ankle">
    <inertial>
      <origin
        xyz="0.0124831744421377 0.00877126170544448 -0.00011006228033858"
        rpy="0 0 0" />
      <mass
        value="0.0401544687611881" />
      <inertia
        ixx="6.22341129865557E-06"
        ixy="1.13806252097995E-07"
        ixz="-3.6295522773617E-08"
        iyy="1.1354072686787E-05"
        iyz="2.17409044982823E-08"
        izz="1.39792054648314E-05" />
    </inertial>
    <visual>
      <origin
        xyz="0 0 0"
        rpy="0 0 0" />
      <geometry>
        <mesh
          filename="package://meshes/r_ankle_visual.STL" /></geometry><material
        name="">
        <color
          rgba="0.752941176470588 0.752941176470588 0.752941176470588 1" />
      </material>
    </visual>
    <collision>
      <origin
        xyz="0 0 0"
        rpy="0 0 0" />
      <geometry>
        <mesh
          filename="package://meshes/r_ankle_respondable.STL" /></geometry></collision>
  </link>
  <joint
    name="r_ankle_x"
    type="revolute">
    <origin
      xyz="0 -0.045 0"
      rpy="-3.1416 1.3878E-15 3.1416" />
    <parent
      link="r_knee" />
    <child
      link="r_ankle" />
    <axis
      xyz="0 0 1" />
    <limit
      lower="-2.6"
      upper="2.6"
      effort="3.1" velocity="7.0" />
  </joint>
  <link
    name="r_foot">
    <inertial>
      <origin
        xyz="-0.0064233398899067 0.020923504968057 3.33167952701469E-05"
        rpy="0 0 0" />
      <mass
        value="0.0202605378538181" />
      <inertia
        ixx="3.14268429568432E-06"
        ixy="3.92584853219292E-07"
        ixz="-3.79765019772885E-09"
        iyy="1.48123918460857E-05"
        iyz="4.33508550050116E-10"
        izz="1.35313300236987E-05" />
    </inertial>
    <visual>
      <origin
        xyz="0 0 0"
        rpy="0 0 0" />
      <geometry>
        <mesh
          filename="package://meshes/r_foot_visual.STL" /></geometry><material
        name="">
        <color
          rgba="1 1 1 1" />
      </material>
    </visual>
    <collision>
      <origin
        xyz="0 0 0"
        rpy="0 0 0" />
      <geometry>
        <mesh
          filename="package://meshes/r_foot_respondable.STL" /></geometry></collision>
  </link>
  <joint
    name="r_foot_y"
    type="revolute">
    <origin
      xyz="0 0 -0.0002"
      rpy="1.3878E-15 8.3267E-15 3.1416" />
    <parent
      link="r_ankle" />
    <child
      link="r_foot" />
    <axis
      xyz="-1 0 0" />
    <limit
      lower="-2.6"
      upper="2.6"
      effort="3.1" velocity="7.0" />
  </joint>
  <link
    name="spine">
    <inertial>
      <origin
        xyz="-2.90372372031417E-05 0.014751453992939 0.00718055086354125"
        rpy="0 0 0" />
      <mass
        value="0.0236192598262425" />
      <inertia
        ixx="4.62186731283792E-06"
        ixy="-3.67948960326759E-10"
        ixz="1.93443312727491E-08"
        iyy="4.35953212647662E-06"
        iyz="-3.88430201433741E-08"
        izz="2.68872368909848E-06" />
    </inertial>
    <visual>
      <origin
        xyz="0 0 0"
        rpy="0 0 0" />
      <geometry>
        <mesh
          filename="package://meshes/spine_visual.STL" /></geometry><material
        name="">
        <color
          rgba="0.752941176470588 0.752941176470588 0.752941176470588 1" />
      </material>
    </visual>
    <collision>
      <origin
        xyz="0 0 0"
        rpy="0 0 0" />
      <geometry>
        <mesh
          filename="package://meshes/spine_respondable.STL" /></geometry></collision>
  </link>
  <joint
    name="spine_z"
    type="revolute">
    <origin
      xyz="0.041652 -0.0728 0.058743"
      rpy="3.1416 0 0" />
    <parent
      link="pelvis" />
    <child
      link="spine" />
    <axis
      xyz="0 -1 0" />
    <limit
      lower="-2.6"
      upper="2.6"
      effort="3.1" velocity="7.0" />
  </joint>
  <link
    name="chest">
    <inertial>
      <origin
        xyz="0.000209217127436427 -0.0105992947731449 0.0552607808779303"
        rpy="0 0 0" />
      <mass
        value="0.08200767006894" />
      <inertia
        ixx="2.88162300657018E-05"
        ixy="1.06916617827795E-07"
        ixz="-1.68144538289912E-11"
        iyy="6.21578509058635E-05"
        iyz="-2.54269141029623E-06"
        izz="5.38555817485431E-05" />
    </inertial>
    <visual>
      <origin
        xyz="0 0 0"
        rpy="0 0 0" />
      <geometry>
        <mesh
          filename="package://meshes/chest_visual.STL" /></geometry><material
        name="">
        <color
          rgba="0.752941176470588 0.752941176470588 0.752941176470588 1" />
      </material>
    </visual>
    <collision>
      <origin
        xyz="0 0 0"
        rpy="0 0 0" />
      <geometry>
        <mesh
          filename="package://meshes/chest_respondable.STL" /></geometry></collision>
  </link>
  <joint
    name="chest_x"
    type="revolute">
    <origin
      xyz="0 0.015 0"
      rpy="-1.5708 0 0" />
    <parent
      link="spine" />
    <child
      link="chest" />
    <axis
      xyz="-1 0 0" />
    <limit
      lower="-2.6"
      upper="2.6"
      effort="3.1" velocity="7.0" />
  </joint>
  <link
    name="l_shoulder">
    <inertial>
      <origin
        xyz="0.00738135253742326 0.00997571314913681 -0.00170181429221082"
        rpy="0 0 0" />
      <mass
        value="0.00334368326561231" />
      <inertia
        ixx="7.55281237044281E-07"
        ixy="2.87316936461553E-15"
        ixz="1.18138638729373E-09"
        iyy="8.36222428966546E-07"
        iyz="-2.95740824446415E-16"
        izz="2.71216334384515E-07" />
    </inertial>
    <visual>
      <origin
        xyz="0 0 0"
        rpy="0 0 0" />
      <geometry>
        <mesh
          filename="package://meshes/l_shoulder_visual.STL" /></geometry><material
        name="">
        <color
          rgba="1 1 1 1" />
      </material>
    </visual>
    <collision>
      <origin
        xyz="0 0 0"
        rpy="0 0 0" />
      <geometry>
        <mesh
          filename="package://meshes/l_shoulder_respondable.STL" /></geometry></collision>
  </link>
  <joint
    name="l_shoulder_x"
    type="revolute">
    <origin
      xyz="-0.0436 -0.00015034 0.051"
      rpy="1.5708 -1.3E-29 3.1416" />
    <parent
      link="chest" />
    <child
      link="l_shoulder" />
    <axis
      xyz="1 0 0" />
    <limit
      lower="-2.6"
      upper="2.6"
      effort="3.1" velocity="7.0" />
  </joint>
  <link
    name="l_shoulder_motor">
    <inertial>
      <origin
        xyz="-1.23621078551815E-05 -0.0128830851143991 -0.00498956108247479"
        rpy="0 0 0" />
      <mass
        value="0.03371809385647" />
      <inertia
        ixx="1.38412199467415E-05"
        ixy="4.44238048547328E-09"
        ixz="3.61149666890659E-09"
        iyy="3.92279038819054E-06"
        iyz="1.82027066691037E-06"
        izz="1.23612082514137E-05" />
    </inertial>
    <visual>
      <origin
        xyz="0 0 0"
        rpy="0 0 0" />
      <geometry>
        <mesh
          filename="package://meshes/l_shoulder_motor_visual.STL" /></geometry><material
        name="">
        <color
          rgba="0.752941176470588 0.752941176470588 0.752941176470588 1" />
      </material>
    </visual>
    <collision>
      <origin
        xyz="0 0 0"
        rpy="0 0 0" />
      <geometry>
        <mesh
          filename="package://meshes/l_shoulder_motor_respondable.STL" /></geometry></collision>
  </link>
  <joint
    name="l_shoulder_motor_y"
    type="revolute">
    <origin
      xyz="0.018 0 0"
      rpy="0 -7.8886E-31 0" />
    <parent
      link="l_shoulder" />
    <child
      link="l_shoulder_motor" />
    <axis
      xyz="0 0 -1" />
    <limit
      lower="-2.6"
      upper="2.6"
      effort="3.1" velocity="7.0" />
  </joint>
  <link
    name="l_upper_arm">
    <inertial>
      <origin
        xyz="-0.00258999199488567 4.39981196477535E-06 0.00172771878614231"
        rpy="0 0 0" />
      <mass
        value="0.00334368326578747" />
      <inertia
        ixx="7.55284120272145E-07"
        ixy="-2.87325888722631E-15"
        ixz="2.82955947450933E-16"
        iyy="8.36222428969736E-07"
        iyz="-2.89665405258988E-16"
        izz="2.71213451173539E-07" />
    </inertial>
    <visual>
      <origin
        xyz="0 0 0"
        rpy="0 0 0" />
      <geometry>
        <mesh
          filename="package://meshes/l_upper_arm_visual.STL" /></geometry><material
        name="">
        <color
          rgba="1 1 1 1" />
      </material>
    </visual>
    <collision>
      <origin
        xyz="0 0 0"
        rpy="0 0 0" />
      <geometry>
        <mesh
          filename="package://meshes/l_upper_arm_respondable.STL" /></geometry></collision>
  </link>
  <joint
    name="l_upper_arm_z"
    type="revolute">
    <origin
      xyz="0 -0.054 0"
      rpy="3.1416 2.0817E-15 -1.5708" />
    <parent
      link="l_shoulder_motor" />
    <child
      link="l_upper_arm" />
    <axis
      xyz="1 0 0" />
    <limit
      lower="-2.6"
      upper="2.6"
      effort="3.1" velocity="7.0" />
  </joint>
  <link
    name="l_forearm">
    <inertial>
      <origin
        xyz="0.00275878256222123 -0.00985811408280605 -0.00151285270170283"
        rpy="0 0 0" />
      <mass
        value="0.0257657351354794" />
      <inertia
        ixx="1.28753735465766E-05"
        ixy="-2.09824525987835E-06"
        ixz="-4.15371891487787E-08"
        iyy="2.70910011838058E-06"
        iyz="-4.0530123233393E-08"
        izz="1.28181627224906E-05" />
    </inertial>
    <visual>
      <origin
        xyz="0 0 0"
        rpy="0 0 0" />
      <geometry>
        <mesh
          filename="package://meshes/l_forearm_visual.STL" /></geometry><material
        name="">
        <color
          rgba="0.752941176470588 0.752941176470588 0.752941176470588 1" />
      </material>
    </visual>
    <collision>
      <origin
        xyz="0 0 0"
        rpy="0 0 0" />
      <geometry>
        <mesh
          filename="package://meshes/l_forearm_respondable.STL" /></geometry></collision>
  </link>
  <joint
    name="l_forearm_y"
    type="revolute">
    <origin
      xyz="0.018 0 0"
      rpy="3.1416 1.1102E-14 -1.5708" />
    <parent
      link="l_upper_arm" />
    <child
      link="l_forearm" />
    <axis
      xyz="0 0 -1" />
    <limit
      lower="-2.6"
      upper="2.6"
      effort="3.1" velocity="7.0" />
  </joint>
  <link
    name="r_shoulder">
    <inertial>
      <origin
        xyz="0.00747429714549365 -0.00997549115221349 -0.00172772501643908"
        rpy="0 0 0" />
      <mass
        value="0.00334368326561429" />
      <inertia
        ixx="7.55284120264203E-07"
        ixy="2.87394589147183E-15"
        ixz="2.43684424781463E-15"
        iyy="8.36222428966732E-07"
        iyz="-1.77903849547866E-16"
        izz="2.7121345116496E-07" />
    </inertial>
    <visual>
      <origin
        xyz="0 0 0"
        rpy="0 0 0" />
      <geometry>
        <mesh
          filename="package://meshes/r_shoulder_visual.STL" /></geometry><material
        name="">
        <color
          rgba="1 1 1 1" />
      </material>
    </visual>
    <collision>
      <origin
        xyz="0 0 0"
        rpy="0 0 0" />
      <geometry>
        <mesh
          filename="package://meshes/r_shoulder_respondable.STL" /></geometry></collision>
  </link>
  <joint
    name="r_shoulder_x"
    type="revolute">
    <origin
      xyz="0.043911 0.00010717 0.051"
      rpy="-1.5708 -1.6935E-18 0.0024405" />
    <parent
      link="chest" />
    <child
      link="r_shoulder" />
    <axis
      xyz="-1 0 0" />
    <limit
      lower="-2.6"
      upper="2.6"
      effort="3.1" velocity="7.0" />
  </joint>
  <link
    name="r_shoulder_motor">
    <inertial>
      <origin
        xyz="-1.4038567669461E-09 -0.012883306710257 -0.00498957709179609"
        rpy="0 0 0" />
      <mass
        value="0.0337180938758863" />
      <inertia
        ixx="1.38412287733881E-05"
        ixy="-7.3500760376234E-14"
        ixz="-5.60187165010458E-13"
        iyy="3.92279039012987E-06"
        iyz="1.82027608688489E-06"
        izz="1.23611994511363E-05" />
    </inertial>
    <visual>
      <origin
        xyz="0 0 0"
        rpy="0 0 0" />
      <geometry>
        <mesh
          filename="package://meshes/r_shoulder_motor_visual.STL" /></geometry><material
        name="">
        <color
          rgba="0.752941176470588 0.752941176470588 0.752941176470588 1" />
      </material>
    </visual>
    <collision>
      <origin
        xyz="0 0 0"
        rpy="0 0 0" />
      <geometry>
        <mesh
          filename="package://meshes/r_shoulder_motor_respondable.STL" /></geometry></collision>
  </link>
  <joint
    name="r_shoulder_motor_y"
    type="revolute">
    <origin
      xyz="0.018089 0 0"
      rpy="-9.8608E-32 4.3368E-19 3.1416" />
    <parent
      link="r_shoulder" />
    <child
      link="r_shoulder_motor" />
    <axis
      xyz="0 0 -1" />
    <limit
      lower="-2.6"
      upper="2.6"
      effort="3.1" velocity="7.0" />
  </joint>
  <link
    name="r_upper_arm">
    <inertial>
      <origin
        xyz="-0.00258977041320127 4.21636392876346E-06 0.00172771994278109"
        rpy="0 0 0" />
      <mass
        value="0.00334368326578746" />
      <inertia
        ixx="7.55284120272144E-07"
        ixy="-2.87003959066501E-15"
        ixz="1.89122636572701E-16"
        iyy="8.36222428969735E-07"
        iyz="-3.2231376407167E-16"
        izz="2.71213451173539E-07" />
    </inertial>
    <visual>
      <origin
        xyz="0 0 0"
        rpy="0 0 0" />
      <geometry>
        <mesh
          filename="package://meshes/r_upper_arm_visual.STL" /></geometry><material
        name="">
        <color
          rgba="1 1 1 1" />
      </material>
    </visual>
    <collision>
      <origin
        xyz="0 0 0"
        rpy="0 0 0" />
      <geometry>
        <mesh
          filename="package://meshes/r_upper_arm_respondable.STL" /></geometry></collision>
  </link>
  <joint
    name="r_upper_arm_z"
    type="revolute">
    <origin
      xyz="0 -0.054 0"
      rpy="-3.1392 6.9389E-16 -1.5708" />
    <parent
      link="r_shoulder_motor" />
    <child
      link="r_upper_arm" />
    <axis
      xyz="1 0 0" />
    <limit
      lower="-2.6"
      upper="2.6"
      effort="3.1" velocity="7.0" />
  </joint>
  <link
    name="r_forearm">
    <inertial>
      <origin
        xyz="-0.0027674219042305 -0.009858408988646 -0.00151302552981825"
        rpy="0 0 0" />
      <mass
        value="0.0257657889801188" />
      <inertia
        ixx="1.28754577391755E-05"
        ixy="2.09826471210378E-06"
        ixz="4.15636504905864E-08"
        iyy="2.7091088250933E-06"
        iyz="-4.03467502127261E-08"
        izz="1.28182439095505E-05" />
    </inertial>
    <visual>
      <origin
        xyz="0 0 0"
        rpy="0 0 0" />
      <geometry>
        <mesh
          filename="package://meshes/r_forearm_visual.STL" /></geometry><material
        name="">
        <color
          rgba="0.752941176470588 0.752941176470588 0.752941176470588 1" />
      </material>
    </visual>
    <collision>
      <origin
        xyz="0 0 0"
        rpy="0 0 0" />
      <geometry>
        <mesh
          filename="package://meshes/r_forearm_respondable.STL" /></geometry></collision>
  </link>
  <joint
    name="r_forearm_y"
    type="revolute">
    <origin
      xyz="0.018 0 0"
      rpy="-3.1416 2.0817E-14 -1.5708" />
    <parent
      link="r_upper_arm" />
    <child
      link="r_forearm" />
    <axis
      xyz="0 0 -1" />
    <limit
      lower="-2.6"
      upper="2.6"
      effort="3.1" velocity="7.0" />
  </joint>
  <link
    name="head">
    <inertial>
      <origin
        xyz="-2.7644991086595E-06 0.0382669003341121 0.00655498269495358"
        rpy="0 0 0" />
      <mass
        value="0.0234153108401363" />
      <inertia
        ixx="1.94365405338274E-05"
        ixy="-5.88434601698114E-10"
        ixz="9.35089278535891E-11"
        iyy="1.81703573504019E-05"
        iyz="1.67170929573408E-06"
        izz="1.80994320349914E-05" />
    </inertial>
    <visual>
      <origin
        xyz="0 0 0"
        rpy="0 0 0" />
      <geometry>
        <mesh
          filename="package://meshes/head_visual.STL" /></geometry><material
        name="">
        <color
          rgba="0.752941176470588 0.752941176470588 0.752941176470588 1" />
      </material>
    </visual>
    <collision>
      <origin
        xyz="0 0 0"
        rpy="0 0 0" />
      <geometry>
        <mesh
          filename="package://meshes/head_respondable.STL" /></geometry></collision>
  </link>
  <joint
    name="head_z"
    type="revolute">
    <origin
      xyz="0.00020517 -0.0021163 0.076016"
      rpy="1.5967 6.4765E-05 -6.3111E-05" />
    <parent
      link="chest" />
    <child
      link="head" />
    <axis
      xyz="0 -1 0" />
    <limit
      lower="-2.6"
      upper="2.6"
      effort="3.1" velocity="7.0" />
  </joint>
</robot>